wait 15 seconds
Bot is ready
CalebP
_ClientEventTask exception was never retrieved
future: <ClientEventTask state=finished event=on_message coro=<bound method BotBase.on_message of <discord.ext.commands.bot.Bot object at 0xb666f4f0>> exception=SystemExit(None)>
Traceback (most recent call last):
  File "/usr/local/lib/python3.7/dist-packages/discord/client.py", line 708, in run
    loop.run_forever()
  File "/usr/lib/python3.7/asyncio/base_events.py", line 539, in run_forever
    self._run_once()
  File "/usr/lib/python3.7/asyncio/base_events.py", line 1775, in _run_once
    handle._run()
  File "/usr/lib/python3.7/asyncio/events.py", line 88, in _run
    self._context.run(self._callback, *self._args)
  File "/usr/local/lib/python3.7/dist-packages/discord/client.py", line 343, in _run_event
    await coro(*args, **kwargs)
  File "/usr/local/lib/python3.7/dist-packages/discord/ext/commands/bot.py", line 942, in on_message
    await self.process_commands(message)
  File "/usr/local/lib/python3.7/dist-packages/discord/ext/commands/bot.py", line 939, in process_commands
    await self.invoke(ctx)
  File "/usr/local/lib/python3.7/dist-packages/discord/ext/commands/bot.py", line 902, in invoke
    await ctx.command.invoke(ctx)
  File "/usr/local/lib/python3.7/dist-packages/discord/ext/commands/core.py", line 864, in invoke
    await injected(*ctx.args, **ctx.kwargs)
  File "/usr/local/lib/python3.7/dist-packages/discord/ext/commands/core.py", line 85, in wrapped
    ret = await coro(*args, **kwargs)
  File "/home/pi/Desktop/Discord/cogs/kill/off.py", line 16, in off
    exit()
  File "/usr/lib/python3.7/_sitebuiltins.py", line 26, in __call__
    raise SystemExit(code)
SystemExit: None
